from fastapi import FastAPI, HTTPException
from pydantic import BaseModel


app = FastAPI()


@app.get('/')
def hello_programmers():
    return {
        "status": 200,
        "message": "Hello Programmers"
    }


@app.get('/users')
def hello_programmers(
        first_name: str,
        last_name: str
    ):
    return {
        "status": 200,
        "message": "Hello Programmers",
        "user": {
            "first_name": first_name,
            "last_name": last_name
        }
    }


@app.get('/default-users')
def hello_programmers(
        first_name: str = 'Default first name',
        last_name: str = "Default last name",
        age: int = 0,
        city: str = 'Bangalore'
    ):
    return {
        "status": 200,
        "message": "Hello Programmers",
        "user": {
            "first_name": first_name,
            "last_name": last_name,
            "age": age,
            "city": city
        }
    }


@app.get('/validate')
def validate_integer_numbers(
        number: str
    ):
    try:
        number = float(number) if '.' in number else int(number)
        return {
            "message": f"{number} is a valid number of {type(number)}"
        } 
    except Exception as error:
        raise HTTPException(status_code=400, detail=f"{number} is a invalid number of {type(number)} -> {error}")


class User(BaseModel):
    first_name: str
    last_name: str
    full_name: str = ''
    username: str
    age: int
    city: str


@app.post("/users/create/")
def create_user(
        user: User
    ):
    user.full_name = f"{user.first_name} {user.last_name}"
    return user

